Workbook

Sheet Product_Data
A1: SKU | B1: Product Name | C1: Brand | D1: Category | E1: Price (₹) | F1: Rating | G1: Reviews | H1: Availability | I1: Listing Status | J1: Title | K1: Description | L1: Images | M1: Bullets | N1: Attributes | O1: Content Completeness | P1: Issue Status | Q1: Priority
A2: SKU001 | B2: DermaGlow Hair Serum | C2: DermaGlow | D2: Hair Care | E2: 299 | F2: 4.5 | G2: 2031 | H2: In Stock | I2: Live | J2: Complete | K2: Missing | L2: Complete | M2: Complete | N2: Complete | O2: =COUNTIF(J2:N2,"Complete")/5 | P2: Content Issue | Q2: Medium
A3: SKU002 | B3: SkinPure Moisturizer | C3: SkinPure | D3: Skincare | E3: 799 | F3: 4.2 | G3: 4622 | H3: In Stock | I3: Live | J3: Complete | K3: Complete | L3: Complete | M3: Complete | N3: Complete | O3: =COUNTIF(J3:N3,"Complete")/5 | P3: No Issue | Q3: Low
A4: SKU003 | B4: SkinPure Conditioner | C4: SkinPure | D4: Hair Care | E4: 1199 | F4: 3.9 | G4: 2301 | H4: Out of Stock | I4: Live | J4: Complete | K4: Complete | L4: Complete | M4: Complete | N4: Complete | O4: =COUNTIF(J4:N4,"Complete")/5 | P4: Availability Issue | Q4: High
A5: SKU004 | B5: DermaGlow Conditioner | C5: DermaGlow | D5: Hair Care | E5: 1199 | F5: 4 | G5: 1047 | H5: In Stock | I5: Suppressed | J5: Missing | K5: Complete | L5: Complete | M5: Complete | N5: Complete | O5: =COUNTIF(J5:N5,"Complete")/5 | P5: Listing Issue | Q5: High
A6: SKU005 | B6: SkinPure Face Wash | C6: SkinPure | D6: Skincare | E6: 499 | F6: 4.9 | G6: 1932 | H6: In Stock | I6: Inactive | J6: Complete | K6: Complete | L6: Complete | M6: Complete | N6: Complete | O6: =COUNTIF(J6:N6,"Complete")/5 | P6: Listing Issue | Q6: Medium
A7: SKU006 | B7: DermaGlow Hair Serum | C7: DermaGlow | D7: Hair Care | E7: 899 | F7: 4.3 | G7: 4400 | H7: In Stock | I7: Live | J7: Complete | K7: Missing | L7: Complete | M7: Complete | N7: Complete | O7: =COUNTIF(J7:N7,"Complete")/5 | P7: Content Issue | Q7: Medium
A8: SKU007 | B8: DermaGlow Body Wash | C8: DermaGlow | D8: Body Care | E8: 449 | F8: 4.6 | G8: 2609 | H8: In Stock | I8: Live | J8: Missing | K8: Complete | L8: Complete | M8: Complete | N8: Complete | O8: =COUNTIF(J8:N8,"Complete")/5 | P8: Content Issue | Q8: Medium
A9: SKU008 | B9: DermaNest Hand Cream | C9: DermaNest | D9: Body Care | E9: 399 | F9: 3.7 | G9: 2045 | H9: In Stock | I9: Live | J9: Complete | K9: Complete | L9: Complete | M9: Complete | N9: Missing | O9: =COUNTIF(J9:N9,"Complete")/5 | P9: Content Issue | Q9: Medium
A10: SKU009 | B10: GlowLab Vitamin C Serum | C10: GlowLab | D10: Skincare | E10: 699 | F10: 3.4 | G10: 410 | H10: Out of Stock | I10: Inactive | J10: Complete | K10: Complete | L10: Complete | M10: Complete | N10: Complete | O10: =COUNTIF(J10:N10,"Complete")/5 | P10: Listing Issue | Q10: High
A11: SKU010 | B11: GlowLab Niacinamide Serum | C11: GlowLab | D11: Skincare | E11: 299 | F11: 4.4 | G11: 963 | H11: In Stock | I11: Live | J11: Complete | K11: Complete | L11: Complete | M11: Complete | N11: Complete | O11: =COUNTIF(J11:N11,"Complete")/5 | P11: No Issue | Q11: Low
A12: SKU011 | B12: Aurelia Care Shampoo | C12: Aurelia Care | D12: Hair Care | E12: 799 | F12: 4.5 | G12: 4183 | H12: Out of Stock | I12: Suppressed | J12: Complete | K12: Complete | L12: Complete | M12: Complete | N12: Missing | O12: =COUNTIF(J12:N12,"Complete")/5 | P12: Listing Issue | Q12: High
A13: SKU012 | B13: GlowLab Conditioner | C13: GlowLab | D13: Hair Care | E13: 299 | F13: 4.2 | G13: 4027 | H13: Out of Stock | I13: Live | J13: Complete | K13: Complete | L13: Complete | M13: Complete | N13: Complete | O13: =COUNTIF(J13:N13,"Complete")/5 | P13: Availability Issue | Q13: High
... A101: SKU100 | B101: Aurelia Care Hair Serum | C101: Aurelia Care | D101: Hair Care | E101: 549 | F101: 4.8 | G101: 3910 | H101: Out of Stock | I101: Live | J101: Complete | K101: Complete | L101: Complete | M101: Complete | N101: Complete | O101: =COUNTIF(J101:N101,"Complete")/5 | P101: Availability Issue | Q101: High

Sheet Issue_Tracker
A1: Issue ID | B1: SKU | C1: Product | D1: Issue Type | E1: Issue Description | F1: Priority | G1: Date Identified | H1: Status | I1: Action Required | J1: Date Resolved
A2: ISS001 | B2: SKU001 | C2: DermaGlow Hair Serum | D2: Content Issue | E2: One or more listing content fields are incomplete | F2: Medium | G2: 2026-09-25 | H2: In Progress | I2: Update missing content
A3: ISS002 | B3: SKU003 | C3: SkinPure Conditioner | D3: Availability Issue | E3: Product is out of stock | F3: High | G3: 2026-09-25 | H3: In Progress | I3: Check inventory availability
A4: ISS003 | B4: SKU004 | C4: DermaGlow Conditioner | D4: Listing Issue | E4: Listing is inactive or suppressed | F4: High | G4: 2026-09-25 | H4: Open | I4: Review listing/catalog suppression
A5: ISS004 | B5: SKU005 | C5: SkinPure Face Wash | D5: Listing Issue | E5: Listing is inactive or suppressed | F5: Medium | G5: 2026-09-25 | H5: Open | I5: Review listing/catalog suppression
A6: ISS005 | B6: SKU006 | C6: DermaGlow Hair Serum | D6: Content Issue | E6: One or more listing content fields are incomplete | F6: Medium | G6: 2026-09-25 | H6: In Progress | I6: Update missing content
A7: ISS006 | B7: SKU007 | C7: DermaGlow Body Wash | D7: Content Issue | E7: One or more listing content fields are incomplete | F7: Medium | G7: 2026-09-25 | H7: In Progress | I7: Update missing content
A8: ISS007 | B8: SKU008 | C8: DermaNest Hand Cream | D8: Content Issue | E8: One or more listing content fields are incomplete | F8: Medium | G8: 2026-09-25 | H8: Resolved | I8: Update missing content | J8: 2026-09-25
A9: ISS008 | B9: SKU009 | C9: GlowLab Vitamin C Serum | D9: Listing Issue | E9: Listing is inactive or suppressed | F9: High | G9: 2026-09-25 | H9: Resolved | I9: Review listing/catalog suppression | J9: 2026-09-25
A10: ISS009 | B10: SKU011 | C10: Aurelia Care Shampoo | D10: Listing Issue | E10: Listing is inactive or suppressed | F10: High | G10: 2026-09-25 | H10: Resolved | I10: Review listing/catalog suppression | J10: 2026-09-25
A11: ISS010 | B11: SKU012 | C11: GlowLab Conditioner | D11: Availability Issue | E11: Product is out of stock | F11: High | G11: 2026-09-25 | H11: Resolved | I11: Check inventory availability | J11: 2026-09-25
A12: ISS011 | B12: SKU013 | C12: DermaGlow Sunscreen | D12: Listing Issue | E12: Listing is inactive or suppressed | F12: High | G12: 2026-09-25 | H12: In Progress | I12: Review listing/catalog suppression
A13: ISS012 | B13: SKU014 | C13: SkinPure Body Lotion | D13: Content Issue | E13: One or more listing content fields are incomplete | F13: Medium | G13: 2026-09-25 | H13: In Progress | I13: Update missing content
A14: ISS013 | B14: SKU016 | C14: SkinPure Face Mask | D14: Content Issue | E14: One or more listing content fields are incomplete | F14: Medium | G14: 2026-09-25 | H14: In Progress | I14: Update missing content
A15: ISS014 | B15: SKU017 | C15: DermaGlow Sunscreen | D15: Availability Issue | E15: Product is out of stock | F15: High | G15: 2026-09-25 | H15: Open | I15: Check inventory availability
A16: ISS015 | B16: SKU018 | C16: DermaGlow Conditioner | D16: Content Issue | E16: One or more listing content fields are incomplete | F16: Medium | G16: 2026-09-25 | H16: In Progress | I16: Update missing content
A17: ISS016 | B17: SKU019 | C17: DermaGlow Face Mask | D17: Listing Issue | E17: Listing is inactive or suppressed | F17: High | G17: 2026-09-25 | H17: Open | I17: Review listing/catalog suppression
A18: ISS017 | B18: SKU020 | C18: SkinPure Face Wash | D18: Content Issue | E18: One or more listing content fields are incomplete | F18: Medium | G18: 2026-09-25 | H18: Open | I18: Update missing content
A19: ISS018 | B19: SKU021 | C19: DermaNest Shampoo | D19: Listing Issue | E19: Listing is inactive or suppressed | F19: High | G19: 2026-09-25 | H19: Resolved | I19: Review listing/catalog suppression | J19: 2026-09-25
A20: ISS019 | B20: SKU022 | C20: DermaGlow Vitamin C Serum | D20: Content Issue | E20: One or more listing content fields are incomplete | F20: Medium | G20: 2026-09-25 | H20: In Progress | I20: Update missing content
A21: ISS020 | B21: SKU023 | C21: GlowLab Face Wash | D21: Availability Issue | E21: Product is out of stock | F21: High | G21: 2026-09-25 | H21: Resolved | I21: Check inventory availability | J21: 2026-09-25
A22: ISS021 | B22: SKU025 | C22: DermaGlow Cleanser | D22: Content Issue | E22: One or more listing content fields are incomplete | F22: Medium | G22: 2026-09-25 | H22: In Progress | I22: Update missing content
A23: ISS022 | B23: SKU026 | C23: Aurelia Care Face Mask | D23: Availability Issue | E23: Product is out of stock | F23: High | G23: 2026-09-25 | H23: Resolved | I23: Check inventory availability | J23: 2026-09-25
A24: ISS023 | B24: SKU028 | C24: DermaNest Shampoo | D24: Content Issue | E24: One or more listing content fields are incomplete | F24: Medium | G24: 2026-09-25 | H24: Resolved | I24: Update missing content | J24: 2026-09-25
A25: ISS024 | B25: SKU029 | C25: DermaNest Vitamin C Serum | D25: Listing Issue | E25: Listing is inactive or suppressed | F25: Medium | G25: 2026-09-25 | H25: Resolved | I25: Review listing/catalog suppression | J25: 2026-09-25
A26: ISS025 | B26: SKU030 | C26: DermaNest Hand Cream | D26: Listing Issue | E26: Listing is inactive or suppressed | F26: High | G26: 2026-09-25 | H26: Resolved | I26: Review listing/catalog suppression | J26: 2026-09-25
A27: ISS026 | B27: SKU031 | C27: SkinPure Conditioner | D27: Content Issue | E27: One or more listing content fields are incomplete | F27: Medium | G27: 2026-09-25 | H27: In Progress | I27: Update missing content
A28: ISS027 | B28: SKU032 | C28: SkinPure Body Wash | D28: Rating Issue | E28: Rating is below 3.8 | F28: Medium | G28: 2026-09-25 | H28: In Progress | I28: Review recurring customer feedback
A29: ISS028 | B29: SKU033 | C29: GlowLab Body Wash | D29: Listing Issue | E29: Listing is inactive or suppressed | F29: Medium | G29: 2026-09-25 | H29: Open | I29: Review listing/catalog suppression
A30: ISS029 | B30: SKU034 | C30: GlowLab Body Lotion | D30: Content Issue | E30: One or more listing content fields are incomplete | F30: Medium | G30: 2026-09-25 | H30: Resolved | I30: Update missing content | J30: 2026-09-25
A31: ISS030 | B31: SKU035 | C31: SkinPure Shampoo | D31: Content Issue | E31: One or more listing content fields are incomplete | F31: Medium | G31: 2026-09-25 | H31: Resolved | I31: Update missing content | J31: 2026-09-25
A32: ISS031 | B32: SKU036 | C32: Aurelia Care Shampoo | D32: Rating Issue | E32: Rating is below 3.8 | F32: Medium | G32: 2026-09-25 | H32: Open | I32: Review recurring customer feedback
A33: ISS032 | B33: SKU037 | C33: Aurelia Care Niacinamide Serum | D33: Content Issue | E33: One or more listing content fields are incomplete | F33: Medium | G33: 2026-09-25 | H33: Open | I33: Update missing content
A34: ISS033 | B34: SKU038 | C34: SkinPure Shampoo | D34: Content Issue | E34: One or more listing content fields are incomplete | F34: Medium | G34: 2026-09-25 | H34: Resolved | I34: Update missing content | J34: 2026-09-25
A35: ISS034 | B35: SKU039 | C35: DermaGlow Vitamin C Serum | D35: Content Issue | E35: One or more listing content fields are incomplete | F35: Medium | G35: 2026-09-25 | H35: Open | I35: Update missing content
A36: ISS035 | B36: SKU040 | C36: SkinPure Body Lotion | D36: Listing Issue | E36: Listing is inactive or suppressed | F36: High | G36: 2026-09-25 | H36: Open | I36: Review listing/catalog suppression
A37: ISS036 | B37: SKU041 | C37: SkinPure Face Mask | D37: Availability Issue | E37: Product is out of stock | F37: High | G37: 2026-09-25 | H37: Open | I37: Check inventory availability
A38: ISS037 | B38: SKU043 | C38: SkinPure Hair Serum | D38: Content Issue | E38: One or more listing content fields are incomplete | F38: Medium | G38: 2026-09-25 | H38: Resolved | I38: Update missing content | J38: 2026-09-25
A39: ISS038 | B39: SKU044 | C39: DermaGlow Moisturizer | D39: Content Issue | E39: One or more listing content fields are incomplete | F39: Medium | G39: 2026-09-25 | H39: In Progress | I39: Update missing content
A40: ISS039 | B40: SKU045 | C40: GlowLab Hand Cream | D40: Content Issue | E40: One or more listing content fields are incomplete | F40: Medium | G40: 2026-09-25 | H40: In Progress | I40: Update missing content
...

Sheet Summary
A1: Marketplace Operations Summary
A3: Total SKUs | B3: =COUNTA(Product_Data!A2:A101) | D3: Listing Status | G3: Priority
A4: Live Listings | B4: =COUNTIF(Product_Data!I2:I101,"Live") | D4: Status | E4: Count | G4: Priority | H4: Count
A5: Inactive Listings | B5: =COUNTIF(Product_Data!I2:I101,"Inactive") | D5: Live | E5: =COUNTIF(Product_Data!I:I,D5) | G5: High | H5: =COUNTIF(Product_Data!Q:Q,G5)
A6: Suppressed Listings | B6: =COUNTIF(Product_Data!I2:I101,"Suppressed") | D6: Inactive | E6: =COUNTIF(Product_Data!I:I,D6) | G6: Medium | H6: =COUNTIF(Product_Data!Q:Q,G6)
A7: Listings With Issues | B7: =COUNTIF(Product_Data!P2:P101,"<>No Issue") | D7: Suppressed | E7: =COUNTIF(Product_Data!I:I,D7) | G7: Low | H7: =COUNTIF(Product_Data!Q:Q,G7)
A8: Average Rating | B8: =AVERAGE(Product_Data!F2:F101)
A9: Average Content Completeness | B9: =AVERAGE(Product_Data!O2:O101)
A10: Open Issues | B10: =COUNTIF(Issue_Tracker!H:H,"Open") | D10: Issue Type
A11: In Progress Issues | B11: =COUNTIF(Issue_Tracker!H:H,"In Progress") | D11: Issue Type | E11: Count
A12: Resolved Issues | B12: =COUNTIF(Issue_Tracker!H:H,"Resolved") | D12: No Issue | E12: =COUNTIF(Product_Data!P:P,D12)
D13: Content Issue | E13: =COUNTIF(Product_Data!P:P,D13)
D14: Availability Issue | E14: =COUNTIF(Product_Data!P:P,D14)
D15: Listing Issue | E15: =COUNTIF(Product_Data!P:P,D15)
D16: Attribute Issue | E16: =COUNTIF(Product_Data!P:P,D16)
D17: Rating Issue | E17: =COUNTIF(Product_Data!P:P,D17)

Sheet Dashboard
A1: E-commerce Marketplace Operations Dashboard
A2: Simulated portfolio project — marketplace catalog health, issue tracking and review analysis
A4: Total SKUs | C4: Live Listings | E4: Suppressed | G4: Listings With Issues
A5: =Summary!B3 | C5: =Summary!B4 | E5: =Summary!B6 | G5: =Summary!B7
A7: Avg Rating | C7: Content Completeness | E7: Open Issues | G7: Resolved Issues
A8: =Summary!B8 | C8: =Summary!B9 | E8: =Summary!B10 | G8: =Summary!B12
A11: Listing Status Summary | D11: Issue Type Summary | G11: Priority Summary
A12: Live | B12: =Summary!E5 | D12: No Issue | E12: =Summary!E12 | G12: High | H12: =Summary!H5
A13: Inactive | B13: =Summary!E6 | D13: Content Issue | E13: =Summary!E13 | G13: Medium | H13: =Summary!H6
A14: Suppressed | B14: =Summary!E7 | D14: Availability Issue | E14: =Summary!E14 | G14: Low | H14: =Summary!H7
D15: Listing Issue | E15: =Summary!E15
D16: Attribute Issue | E16: =Summary!E16
D17: Rating Issue | E17: =Summary!E17
A36: Operational Review Checklist
A37: • Audit inactive and suppressed listings
A38: • Review incomplete product content
A39: • Check out-of-stock products
A40: • Review recurring low-rating / negative feedback
A41: • Follow up on open marketplace issues
A42: • Verify resolved issues and update trackers
